Workbook
Name mos: '[1]Общие данные'!$C$23:$D$23
Name mos: '[2]Общие данные'!$C$23:$D$23
Name mos: '[3]Общие данные'!$C$23:$D$23
Name mulk: '[1]Общие данные'!$C$24:$W$24
Name mulk: '[2]Общие данные'!$C$24:$W$24
Name mulk: '[3]Общие данные'!$C$24:$W$24

Sheet Протокол  (2)
A1: =""&'Общие данные'!B158&" mikromoliya tashkiloti Kredit qo‘mitasining yig‘ilishi" -> «PULLOL BUSINESS MIKROMOLIYA TASHKILOTI» MChJ mikromoliya tashkiloti Kredit qo‘mitasining yig‘ilishi
A2: =""&H7&" protokolidan ko'chirma" -> № 323-BR protokolidan ko'chirma
A3: Toshkent shahri | E3: ='Общие данные'!B68 -> 7 aprel 2026 y.
B4: KUN TARTIBI:
A5: =" "&H8&"."&'Общие данные'!B5&" ga "&'Общие данные'!B65&" berish masalasini ko‘rib chiqish to‘g‘risida." -> 1.ALLAMURODOV MUHAMMAD YOQUB O‘G‘LI ga mikroqarz berish masalasini ko‘rib chiqish to‘g‘risida.
A7: =" "&H9&" masala yuzasidan: "&'Общие данные'!B158&" mikromoliya tashkiloti kredit bo‘yicha menejeri "&'Общие данные'!B5&"ga "&FIXED('Общие данные'!B76)&" ("&'Общие данные'!B77&") so‘m miqdorida, muddati "&'Общие данные'!B82&" ("&'Общие данные'!B83&") oyga va yillik "&'Общие данные'!B86&" %("&'Общие данные'!B87&") foiz miqdorida "&'Общие данные'!B65&" berich bo‘yicha "&'Общие данные'!B5&"ning kredit arizasi va "&'Общие данные'!B158&"ning xulosasi bilan ishtirokchilarni tanishtirdi." -> Birinchi masala yuzasidan: «PULLOL BUSINESS MIKROMOLIYA TASHKILOTI» MChJ mikromoliya tashkiloti kredit bo‘yicha menejeri ALLAMURODOV MUHAMMAD YOQUB O‘G‘LIga 52 000 000,00 (ellik ikki million so'm) so‘m miqdorida, muddati 36 (O'ttiz olti ) oyga va yillik 55 %(Ellik besh ) foiz miqdorida mikroqarz berich bo‘yicha ALLAMURODOV MUHAMMAD YOQUB O‘G‘LIning kredit arizasi va «PULLOL BUSINESS MIKROMOLIYA TASHKILOTI» MChJning xulosasi bilan ishtirokchilarni tanishtirdi. | G7: Protokol raqami | H7: ='Общие данные'!B1 -> № 323-BR
G8: Savol raqami | H8: 1 | I8: 1 | J8: 2 | K8: 3 | L8: 4 | M8: 5 | N8: 6 | O8: 7 | P8: 8 | Q8: 9 | R8: 10 | S8: 11 | T8: 12 | U8: 13 | V8: 14 | W8: 15 | X8: 16 | Y8: 17 | Z8: 18 | AA8: 19 | AB8: 20 | AC8: 21 | AD8: 22 | AE8: 23 | AF8: 24 | AG8: 25
G9: Savol raqami qol bilan | H9: =IF(H8=I8,I9,IF(H8=J8,J9,IF(H8=K8,K9,IF(H8=L8,L9,IF(H8=M8,M9,IF(H8=N8,N9,IF(H8=O8,O9,IF(H8=P8,P9,IF(H8=Q8,Q9,IF(H8=R8,R9,IF(H8=S8,S9,IF(H8=T8,T9,IF(H8=U8,U9,IF(H8=V8,V9,IF(H8=W8,W9,IF(H8=X8,X9,IF(H8=Y8,Y9,IF(H8=Z8,Z9,IF(H8=AA8,AA9,IF(H8=AB8,AB9,IF(H8=AC8,AC9,IF(H8=AD8,AD9,IF(H8=AE8,AE9,IF(H8=AF8,AF9,IF(H8=AG8,AG9))))))))))))))))))))))))) -> Birinchi | I9: Birinchi | J9: Ikkinchi | K9: Uchinchi | L9: To'rtinchi | M9: Beshinchi | N9: O'ltinchi | O9: Yettinchi | P9: Sakkizinchi | Q9: Tuqqizinchi | R9: O'ninchi | S9: O'n birinchi | T9: O'n ikkinchi | U9: O'n uchinchi | V9: O'n to'rtinchi | W9: O'n beshinchi | X9: O'n oltinchi | Y9: O'n yettinchi | Z9: O'n sakkizinchi | AA9: O'n tuqqizinchi | AB9: Yigirmanchi | AC9: Yigirma birinchi | AD9: Yigizma ikkinchi | AE9: Yigirma uchinchi | AF9: Yigirma to'rtinchi | AG9: Yigirma beshinchi
A11: =""&'Общие данные'!C64&" ta’minoti:" -> Mikroqarz ta’minoti:
A13: ='Заключение КК'!A18:E18 -> 1. Egalik huquqi RO'ZIYEV ODILJON OLIMJONOVICHga tegishli bo'lgan garovga olingan avtomobil markasi SPARK, rangi - OQ BELAYA, ishlab chiqarilgan yili - 2018, davlat raqam belgisi 80F845XA, kuzov turi - YENGIL SEDAN, kuzov raqami XWBMF48NEJA525204, dvigatel raqami B15D212181062B8JX0417, shassi raqami - RAKAMSIZ
A14: ="2. «"&'Общие данные'!B154&"» АJ sug‘urta kompaniyasi tomonidan Mikroqarz to'lamaslik xavfini "&FIXED('Общие данные'!B155,2)&"("&'Общие данные'!B156&") so ' m miqdoriga sug’urta qilish" -> 2. «АО СК "IMPEX INSURANCE"» АJ sug‘urta kompaniyasi tomonidan Mikroqarz to'lamaslik xavfini 23 800 000,00(yigirma uch million sakkiz yuz ming so'm) so ' m miqdoriga sug’urta qilish
C15: masala yuzasidan berilgan ma’lumotlarni muhokama qilib, Kredit qo‘mitasi a’zolariga taqdim etilgan zarur hujjatlarni o‘rganib, majlisda ishtirok etgan Kredit qo‘mitasi a’zolarining taklif va mulohazalarini inobatga olgan holda | D15: =""&'Общие данные'!B158&" kredit qo‘mitasi" -> «PULLOL BUSINESS MIKROMOLIYA TASHKILOTI» MChJ kredit qo‘mitasi | E15: =CONCATENATE(C15,D15) -> masala yuzasidan berilgan ma’lumotlarni muhokama qilib, Kredit qo‘mitasi a’zolariga taqdim etilgan zarur hujjatlarni o‘rganib, majlisda ishtirok etgan Kredit qo‘mitasi a’zolarining taklif va mulohazalarini inobatga olgan holda «PULLOL BUSINESS MIKROMOLIYA TASHKILOTI» MChJ kredit qo‘mitasi
A16: =CONCATENATE(H9,E15) -> Birinchi masala yuzasidan berilgan ma’lumotlarni muhokama qilib, Kredit qo‘mitasi a’zolariga taqdim etilgan zarur hujjatlarni o‘rganib, majlisda ishtirok etgan Kredit qo‘mitasi a’zolarining taklif va mulohazalarini inobatga olgan holda «PULLOL BUSINESS MIKROMOLIYA TASHKILOTI» MChJ kredit qo‘mitasi
A17: QAROR QILADI:
A18: =" "&'Общие данные'!B5&"ga quyidagi shartlarda "&'Общие данные'!B65&" berish masalasi ma’qullansin:" -> ALLAMURODOV MUHAMMAD YOQUB O‘G‘LIga quyidagi shartlarda mikroqarz berish masalasi ma’qullansin:
A19: ="1. "&'Общие данные'!C64&" summasi: "&FIXED('Общие данные'!B76)&" ("&'Общие данные'!B77&") so'm." -> 1. Mikroqarz summasi: 52 000 000,00 (ellik ikki million so'm) so'm.
A20: ="2. "&'Общие данные'!C64&" muddati: "&'Общие данные'!B82&" ("&'Общие данные'!B83&") oy " -> 2. Mikroqarz muddati: 36 (O'ttiz olti ) oy
A21: ="3. "&'Общие данные'!C64&"dan foydalanganlik uchun foiz stavkasi:yillik "&'Общие данные'!B86&"% ("&'Общие данные'!B87&") foiz." -> 3. Mikroqarzdan foydalanganlik uchun foiz stavkasi:yillik 55% (Ellik besh ) foiz.
A22: ="4. "&'Общие данные'!C64&" bo‘yicha asosiy qarz va foizlarni to‘lash:" -> 4. Mikroqarz bo‘yicha asosiy qarz va foizlarni to‘lash:
A23: ='Кредитная заявка'!A19:D19 -> - mikroqarz shartnomasi bo'yicha har oy differensial to'lovlari amalga oshiriladi
A24: ="5. "&'Общие данные'!C64&" bo‘yicha ta'minot:" -> 5. Mikroqarz bo‘yicha ta'minot:
A25: ="1. garov "&'Заключение КК'!A29:E29&"" -> 1. garov - RO'ZIYEV ODILJON OLIMJONOVICH ga mulk huquqi asosida tegishli avtotransport vositasi SPARK , quyidagi tafsilotlarga muvofiq:
A26: ='Акт согласования'!A29 -> Nomi | B26: ='Акт согласования'!B29 -> Kuzov turi va kuzov raqami* | C26: ='Акт согласования'!C29 -> Dvigatel va shassi raqami* | D26: ='Акт согласования'!D29 -> Ishlab chiqarilgan yili va rangi* | E26: ='Акт согласования'!E29 -> Kelishilgan garov qiymati, so'm
A27: ='Акт согласования'!A30 -> SPARK | B27: ='Акт согласования'!B30 -> kuzov turi - YENGIL SEDAN, kuzov raqami XWBMF48NEJA525204 | C27: ='Акт согласования'!C30 -> dvigatel raqami B15D212181062B8JX0417, shassi raqami - RAKAMSIZ | D27: ='Акт согласования'!D30 -> rangi - OQ BELAYA, ishlab chiqarilgan yili - 2018 | E27: ='Акт согласования'!E30 -> 49 000 000,00 (qirq to'qqiz million so'm)
A28: ='Акт согласования'!A22:E22 -> -* avtotransport egasi: RO'ZIYEV ODILJON OLIMJONOVICH
A29: ='Акт согласования'!A23:E23 -> -* texnik pasport: AAG 2554881 10.10.2023 y
A30: ='Акт согласования'!A24:E24 -> -* roʻyxatdan oʻtgan manzili/garaj manzili: BUXORO VILOYATI OLOT TUMANI ASAJAM MFY ASAJAM
A31: ='Акт согласования'!A25:E25 -> -* davlat raqami: 80F845XA
A33: ="6. «"&'Общие данные'!B154&"» АJ sug‘urta kompaniyasi tomonidan "&'Общие данные'!C64&" to'lamaslik xavfini "&FIXED('Общие данные'!B155,2)&"("&'Общие данные'!B156&") so ' m miqdoriga sug’urta qilish" -> 6. «АО СК "IMPEX INSURANCE"» АJ sug‘urta kompaniyasi tomonidan Mikroqarz to'lamaslik xavfini 23 800 000,00(yigirma uch million sakkiz yuz ming so'm) so ' m miqdoriga sug’urta qilish
A34: ="7. Boshqa shartlar – "&IF('Общие данные'!B110='Общие данные'!B111,"avtotransport vositasi",IF('Общие данные'!B110='Общие данные'!C111,"ko'chmas mulk",0))&" shaklida garov ta'minlangandan keyin "&'Общие данные'!B65&" berish." -> 7. Boshqa shartlar – 0 shaklida garov ta'minlangandan keyin mikroqarz berish.
A36: Qaror bir ovozdan qabul qilindi.
A41: ='Общие данные'!B158&" direktori v.v.b." -> «PULLOL BUSINESS MIKROMOLIYA TASHKILOTI» MChJ direktori v.v.b. | D41: ='Общие данные'!B161 -> Mominov B. X.
A45: ='Общие данные'!A170 -> Kreditlash bo’limi boshlig’i | D45: ='Общие данные'!B170 -> Akramov R.N.
A48: ='Общие данные'!A171 -> Buxoro filiali boshlig’i | D48: ='Общие данные'!B171 -> Ikromov B.A.
A49: ='Общие данные'!A172 -> Kredit bo'limi menejeri | D49: ='Общие данные'!B172 -> Eshbekov S. O.

Sheet Общие данные
A1: =CONCATENATE(B65," olish uchun ariza") -> mikroqarz olish uchun ariza | B1: № 323-BR
A2: =CONCATENATE(B65," olish uchun ariza sanasi QO’L BILAN KIRITILADI") -> mikroqarz olish uchun ariza sanasi QO’L BILAN KIRITILADI | B2: 07.04.2026 | D2: =180+B2 -> 46299
A4: Qarz oluvchi bo’yicha ma’lumotlar
A5: Ariza beruvchining FISh (kim? – Ibragimov Rustam Sadikovich) | B5: ALLAMURODOV MUHAMMAD YOQUB O‘G‘LI
A6: agar o’zgarishlar bo’lgan bo’lsa oldingi FISh (Sadikov Rustam Sadikovich yoki yo’q) | B6: yoq | C6: ha | D6: yo’q
A7: Ariza beruvchining FISh (kim? – Ibragimov R.S.) | B7: ALLAMURODOV M.Y.
A8: FISh (ariza kimdan? – Ibragimov Rustam Sadikovichdan) | B8: =B5 -> ALLAMURODOV MUHAMMAD YOQUB O‘G‘LI
A9: FISh (kimdan? – Ibragimov R.S.dan) | B9: =B7 -> ALLAMURODOV M.Y.
A10: FISh (kimga? – Ibragimov Rustam Sadikovichga) | B10: =B8 -> ALLAMURODOV MUHAMMAD YOQUB O‘G‘LI
A11: FISh (kimga? – Ibragimov R.S.ga) | B11: =B9 -> ALLAMURODOV M.Y.
A12: FISh (kim bilan? – Ibragimov Rustam Sadikovich bilan) | B12: =B10 -> ALLAMURODOV MUHAMMAD YOQUB O‘G‘LI
A13: FISh (kim bilan? – Ibragimov R.S. bilan) | B13: =B11 -> ALLAMURODOV M.Y.
A14: Fuqaroligi (O’zbekiston Respublikasi) | B14: O’zbekiston Respublikasi
A15: Tug’ilgan sanasi (01.10.2011 yil) | B15: 24.05.1993 y
A16: Pasport seriyasi (СА №1234567) | B16: AD 9213848
B17: IIV 61013 | D17: =TEXT(C17,"ДД.ММ.ГГГГ") -> 00.01.1900
B18: 45596 | C18: =TEXT(B18,"ДД.ММ.ГГГГ") -> 31.10.2024
B19: 49247 | C19: =TEXT(B19,"ДД.ММ.ГГГГ") -> 30.10.2034
A20: Kim va qachon berilgan (Toshkent shahri Chilonzor IIB tomonidan 2011 yil __.____) | B20: =""&B17&" tomonidan "&C18&" yilda berilgan" -> IIV 61013 tomonidan 31.10.2024 yilda berilgan | C20: =""&B17&" tomonidan "&C18&" yilda berilgan" -> IIV 61013 tomonidan 31.10.2024 yilda berilgan
A21: Pasportni amal qilish muddati (01.10.2011 yilgacha / yoki muddatsiz) | B21: =""&C19&" y." -> 30.10.2034 y. | C21: =""&C19&" yilgacha" -> 30.10.2034 yilgacha
A22: doimiy ro’yhatdan o’tgan joyi (Toshkent sh., Mirobod tumani, Nukus ko’chasi, 1 uy, 1 honadon) | B22: BUXORO VILOYATI KOGON TUMANI SORG'UN MFY PARAKATI QQ 22-UY | C22: =TEXT(B19,"ДД.ММ.ГГГГ") -> 30.10.2034
A23: doimiy ro’yhatdan o’tgan joyi haqiqatdagi turar joyi bilan mos keladi/mos kelmaydi | B23: mos keladi | C23: mos keladi | D23: mos kelmaydi
A24: Ro’yhatdan o’tish joyida yashash asosi | B24: Mulk huquqi | C24: Mulk huquqi | D24: ijara | E24: служебная | F24: другое | G24: -
A25: Telefon raqami kod bilan ((99871) 277 77 77) | B25: 93 137 50 56 KLIENT
A26: Mo’ljal | B26: 7-MAKTAB
B27: =IF(B23="mos keladi",B22,B28) -> BUXORO VILOYATI KOGON TUMANI SORG'UN MFY PARAKATI QQ 22-UY
A28: Haqiqatdagi yashash joyi (Toshkent sh., Mirobod tumani, Nukus ko’chasi, 1 uy, 1 honadon) | B28: BUXORO VILOYATI KOGON TUMANI SORG'UN MFY PARAKATI QQ 22-UY
A29: Haqiqatdagi yashash joyida turish asosi | B29: Mulk huquqi | C29: Mulk huquqi | D29: ijara | E29: xizmat | F29: boshqa | G29: -
A30: Mijozning jinsi | B30: erkak | C30: erkak | D30: ayol
A31: Tug’ilgan joyi (Toshkent) | B31: KOGON TUMANI
A32: Fuqaroligi (O’zbekiston Respublikasi) | B32: O’zbekiston Respublikasi
A33: Telefon raqami kod bilan ((99871) 277 77 77) | B33: =B25 -> 93 137 50 56 KLIENT
B34: =IF(B23="mos keladi",B26,B35) -> 7-MAKTAB
A35: Mo’ljal
A36: Oilaviy ahvoli
A37: Oila a'zolari soni (jami):
A38: Ma’lumoti
A39: Mutaxassisligi
A40: Ish telefoni raqami kod bilan ((99890) 3270000) | B40: =B25 -> 93 137 50 56 KLIENT
A41: Mobil telefon raqami kod bilan ((99890) 3270000) | B41: 91 247 01 98 UKASI
...

Sheet Анкета Клиента
A1: MIJOZNING ANKETASI
A2: Anketa kredit menejeri tomonidan mijozning javoblarini kiritish orqali to'ldiriladi, kerak bo'lganda, Mijoz tomonidan tanlangan javob variantlarini belgilash orqali amalga oshiriladi
A3: 1. MIJOZ HAQIDA MA'LUMOTLAR:
A4: ='Заключение КК'!A4:E4 -> Mijozning to'liq ismi sharifi: ALLAMURODOV MUHAMMAD YOQUB O‘G‘LI
A5: ='Заключение КК'!A5:E5 -> Tug'ilgan sanasi: 24.05.1993 y
A6: ='Заключение КК'!A6:E6 -> Pasport seriyasi AD 9213848 IIV 61013 tomonidan 31.10.2024 yilda berilgan, amal qilish muddati - 30.10.2034 y.
A7: ="Fuqaroligi: "&'Общие данные'!B32&"" -> Fuqaroligi: O’zbekiston Respublikasi
A8: ='Заключение КК'!A7:E7 -> Ro‘yxatdan o‘tgan manzili: BUXORO VILOYATI KOGON TUMANI SORG'UN MFY PARAKATI QQ 22-UY, mo'ljal: 7-MAKTAB
A9: =IF('Общие данные'!B23="mos keladi"," ",'Анкета Клиента'!A10:F10)
A10: ="Haqiqatdan yashash joy manzili: "&'Общие данные'!B28&"" -> Haqiqatdan yashash joy manzili: BUXORO VILOYATI KOGON TUMANI SORG'UN MFY PARAKATI QQ 22-UY
A11: ='Заключение КК'!A8:E8 -> Ish joyi: lavozimi Йўловчиларни енгил автотранспорт воситаларида ташишda O'Z O'ZINI BAND QILGAN FUQARO MA'LUMOTNOMA № № 0013114001
A12: 2. Mijoz bilan ulanich uchun aloqa ma'lumotlari:
A13: ="Uy telefoni raqami: "&'Общие данные'!B40&"" -> Uy telefoni raqami: 93 137 50 56 KLIENT
A14: ="Uyali telefon raqami: "&'Общие данные'!B41&"" -> Uyali telefon raqami: 91 247 01 98 UKASI
A15: ="Uyali telefon raqami: "&'Общие данные'!B42&"" -> Uyali telefon raqami: 93 392 24 05 AYOLI
A16: ="Uyali telefon raqami: "&'Общие данные'!B42&"" -> Uyali telefon raqami: 93 392 24 05 AYOLI
A17: ="Ish telefoni raqami: "&'Общие данные'!B43&"" -> Ish telefoni raqami:
A18: 3. MIJOZNING ISH JOYI HAQIDA MA'LUMOT:
A19: ="Muassasa nomlanishi:"&'Общие данные'!B58&"" -> Muassasa nomlanishi:O'Z O'ZINI BAND QILGAN FUQARO MA'LUMOTNOMA № № 0013114001
A20: ="Ro‘yxatdan o‘tish manzili:"&'Общие данные'!B50&"" -> Ro‘yxatdan o‘tish manzili:Бухоро вилояти Когон тумани
A21: ="Lavozimi: "&'Общие данные'!B48&"" -> Lavozimi: Йўловчиларни енгил автотранспорт воситаларида ташиш
A22: 4. MIJOZNING OYLIK DAROMADLARI VA XARAJATLARI HAQIDA MA'LUMOT
A23: Daromad manbalari | B23: Mijoz | C23: Turmush o'rtog'i | D23: Boshqa oila a'zolari | E23: Xarajatlar | F23: Мiqdori
A24: ish haqi (asosiy ish) | B24: ='Общие данные'!B60 -> 8000000 | C24: 0 | D24: 0 | E24: uy-joy va kommunal xizmatlar uchun to'lov | F24: 700000
A25: ish haqi (o‘rindoshlik) | B25: 0 | C25: 0 | D25: 0 | E25: oilaviy xarajatlar | F25: 500000
A26: boshqa daromadlar | B26: ='Общие данные'!B61 -> 5000000 | C26: 0 | D26: 0 | E26: boshqa xarajatlar | F26: 600000
A27: JAMI | B27: =B24+B25+B26 -> 13000000 | C27: =SUM(C24:C26) -> 0 | D27: =SUM(D24:D26) -> 0 | F27: =SUM(F24:F26) -> 1800000
A28: ="Men, "&'Общие данные'!B5&", ushbu anketada ko‘rsatilgan barcha ma'lumotlar anketa to'ldirilgan sanada to'g'ri va aniq ekanligini tasdiqlayman." -> Men, ALLAMURODOV MUHAMMAD YOQUB O‘G‘LI, ushbu anketada ko‘rsatilgan barcha ma'lumotlar anketa to'ldirilgan sanada to'g'ri va aniq ekanligini tasdiqlayman.
A29: ="Men, "&'Общие данные'!B5&", quyidagilarni tan olaman va roziman::" -> Men, ALLAMURODOV MUHAMMAD YOQUB O‘G‘LI, quyidagilarni tan olaman va roziman::
A30: ="1. Ushbu anketada ko‘rsatilgan har qanday ma’lumot "&'Общие данные'!B158&", uning xodimlari va huquqiy vorislari tomonidan istalgan manbaa va ma’lumotlardan foydalangan holda istalgan vaqtda tekshirilishi va qayta tekshirilishi mumkin." -> 1. Ushbu anketada ko‘rsatilgan har qanday ma’lumot «PULLOL BUSINESS MIKROMOLIYA TASHKILOTI» MChJ, uning xodimlari va huquqiy vorislari tomonidan istalgan manbaa va ma’lumotlardan foydalangan holda istalgan vaqtda tekshirilishi va qayta tekshirilishi mumkin.
A31: ="2. Mazkur anketaning "&'Общие данные'!B158&" tomonidan qabul qilinishi "&'Общие данные'!B158&" tomonidan menga "&'Общие данные'!B65&" berish majburiyatini yuklamaydi." -> 2. Mazkur anketaning «PULLOL BUSINESS MIKROMOLIYA TASHKILOTI» MChJ tomonidan qabul qilinishi «PULLOL BUSINESS MIKROMOLIYA TASHKILOTI» MChJ tomonidan menga mikroqarz berish majburiyatini yuklamaydi.
A32: Men, _________________________________________________________________ (to'liq ismi sharifi), ushbu anketadagi barcha ma'lumotlar anketa to'ldirilgan sanada to'g'ri ekanligini tasdiqlayman va ushbu anketaning 1- va 2-bandlarini tan olaman va ularga rozilik bildiraman. Mazkur anketaning 4-bo'limida ko'rsatilgan daromadlarim haqidagi ma'lumotlarni qabul qilishingizni va moliyaviy tahlilda foydalanishingizni so’rayman.
A34: Mijozning to'liq ismi sharifi | D34: Sana | E34: Imzo
D35: ='Общие данные'!B2 -> 07.04.2026

Sheet Анкета 2
A2: ANKETA
E3: ='Общие данные'!B68 -> 7 aprel 2026 y.
A5: Mijozning to'liq ismi sharifi | C5: ='Общие данные'!B8 -> ALLAMURODOV MUHAMMAD YOQUB O‘G‘LI
A7: Siz ommaviy mansabdor shaxsmisiz? | D7: Ha
D8: Yo'q
A9: Yaqin qarindoshlaringiz orasida ommaviy mansabdor shaxslar bormi? | D9: Ha
D10: Yo'q
A11: Do'stlaringiz yoki yaqinlaringizdan birontasi ommaviy mansabdor shaxsmi? | D11: Ha
D12: Yo'q
A13: Yuqoridagi savollardan biriga «Ha» deb javob bergan bo'lsangiz, javobingizni qisqacha tushuntirib bering:
A18: Siz bank amaliyotlarini amalga oshirishda uchinchi shaxsning manfaatlarini ifodalaysizmi? | D18: Ha
D19: Yo'q
A20: Agar oldingi savolga «HA» deb javob bergan bo'lsangiz, bank operatsiyalarini bajarich uchun ishonchnomangiz bormi? | D20: Ha
D21: Yo'q
A23: Agar oldingi savolga «YO'Q» deb javob bergan bo'lsangiz, javobingizni qisqacha tushuntirib bering:
A28: Ommaviy mansabdor shaxslar — doimiy, vaqtincha yoki maxsus vakolatli organ tomonidan tayinlangan yoki saylangan, tashkiliy-maʼmuriy funktsiyalarni bajaruvchi hamda xorijiy davlatning qonun chiqaruvchi, ijro etuvchi, maʼmuriy yoki sud organida yoxud xalqaro tashkilotda yuridik ahamiyatga molik harakatlarni amalga oshirishga vakolatli shaxslar, shuningdek xorijiy davlatlar korxonalarining yuqori martabali rahbarlari, taniqli siyosatchilar va xorijiy davlatlar siyosiy partiyalarining taniqli a'zolari.
A30: Anketadagi barcha ma'lumotlar to'g'ri, agar o'zgarishlar bo'lsa, men bu haqida xabardor qilish majburiyatini o'z zimmamga olaman.
A33: =C5 -> ALLAMURODOV MUHAMMAD YOQUB O‘G‘LI

Sheet Кредитная заявка
C1: =""&'Общие данные'!B158&"ning "&'Общие данные'!A171&"" -> «PULLOL BUSINESS MIKROMOLIYA TASHKILOTI» MChJning Buxoro filiali boshlig’i
D2: =""&'Общие данные'!C171&"ga" -> B.A.Ikromovga
A4: =""&'Общие данные'!C64&" olish uchun Ariza" -> Mikroqarz olish uchun Ariza
A6: =""&'Общие данные'!B28&".-da yashovchi O‘zbekiston Respublikasi fuqarosi "&'Общие данные'!B8&"dan. " -> BUXORO VILOYATI KOGON TUMANI SORG'UN MFY PARAKATI QQ 22-UY.-da yashovchi O‘zbekiston Respublikasi fuqarosi ALLAMURODOV MUHAMMAD YOQUB O‘G‘LIdan.
A7: ="Tug'ilgan kuni: "&'Общие данные'!B15&"" -> Tug'ilgan kuni: 24.05.1993 y
A8: ="Pasport seriyasi: "&'Общие данные'!B16&" "&'Общие данные'!B20&"" -> Pasport seriyasi: AD 9213848 IIV 61013 tomonidan 31.10.2024 yilda berilgan
A9: ="Asosiy ish joyi : "&'Общие данные'!B58&"" -> Asosiy ish joyi : O'Z O'ZINI BAND QILGAN FUQARO MA'LUMOTNOMA № № 0013114001
A10: ="Lavozimi: "&'Общие данные'!B59&"" -> Lavozimi: Йўловчиларни енгил автотранспорт воситаларида ташиш
A11: ="O’rtacha oylik daromadi: "&FIXED('Анкета Клиента'!B27,2)&" so'm." -> O’rtacha oylik daromadi: 13 000 000,00 so'm.
A12: ="Menga quyidagi shartlarda "&'Общие данные'!B65&" berishingizni so’rayman:" -> Menga quyidagi shartlarda mikroqarz berishingizni so’rayman:
A13: =""&'Общие данные'!C64&" summasi: "&FIXED('Общие данные'!B76,2)&" ("&'Общие данные'!B77&") so'm." -> Mikroqarz summasi: 52 000 000,00 (ellik ikki million so'm) so'm.
A14: =""&'Общие данные'!C64&" muddati: "&'Общие данные'!B82&" ("&'Общие данные'!B83&") oy." -> Mikroqarz muddati: 36 (O'ttiz olti ) oy.
A15: =""&'Общие данные'!C64&"dan foydalanganlik uchun foiz stavkasi: yillik "&'Общие данные'!B86&"% ("&'Общие данные'!B87&") foiz" -> Mikroqarzdan foydalanganlik uchun foiz stavkasi: yillik 55% (Ellik besh ) foiz
A16: =""&'Общие данные'!C64&" bo'yicha asosiy qarz va foizlarni to'lash:" -> Mikroqarz bo'yicha asosiy qarz va foizlarni to'lash:
A17: =" - "&'Общие данные'!B65&" shartnomasi bo'yicha har oy differensial to'lovlari amalga oshiriladi" -> - mikroqarz shartnomasi bo'yicha har oy differensial to'lovlari amalga oshiriladi
A18: =" - "&'Общие данные'!B65&" shartnomasi bo'yicha har oy annuitet to'lovlari amalga oshiriladi" -> - mikroqarz shartnomasi bo'yicha har oy annuitet to'lovlari amalga oshiriladi
A19: =IF('Общие данные'!B78='Общие данные'!C78,'Кредитная заявка'!A17:D17,IF('Общие данные'!B78='Общие данные'!D78,'Кредитная заявка'!A18:D18)) -> - mikroqarz shartnomasi bo'yicha har oy differensial to'lovlari amalga oshiriladi
A20: =IF(DAY('Общие данные'!E67)<15," "," Oxirgi yakuniy to'lov "&'Общие данные'!B65&" shartnomasi tuzilgan kundan boshlab oxirgi oyning oxirgi kunida amalga oshiriladi")
A21: =""&'Общие данные'!C64&" ta’minoti::" -> Mikroqarz ta’minoti::
A22: ="1. "&IF('Общие данные'!B110="Avtotransport",A26,A23)&"" -> 1. Egalik huquqi RO'ZIYEV ODILJON OLIMJONOVICHga tegishli bo'lgan garovga olingan avtomobil markasi SPARK, rangi - OQ BELAYA, ishlab chiqarilgan yili - 2018, davlat raqam belgisi 80F845XA, kuzov turi - YENGIL SEDAN, kuzov raqami XWBMF48NEJA525204, dvigatel raqami B15D212181062B8JX0417, shassi raqami - RAKAMSIZ
A23: =IF('Общие данные'!B99='Общие данные'!C99,A25,IF('Общие данные'!B99='Общие данные'!D99,A24,0)) -> Egalik huquqi 0ga tegishli bo'lgan umumiy maydoni - va yashash maydoni - 0,
A24: =" - Navbatdagi garov (ipoteka) Egalik huquqi asosida "&'Общие данные'!C124&"ga "&'Общие данные'!C133&", umumiy maydoni - "&'Общие данные'!C137&" va yashash maydoni - "&'Общие данные'!C140&", manzili: "&'Общие данные'!C130&"." -> - Navbatdagi garov (ipoteka) Egalik huquqi asosida 0ga 0, umumiy maydoni - va yashash maydoni - , manzili: .
A25: =" Egalik huquqi "&'Общие данные'!C124&"ga tegishli bo'lgan umumiy maydoni - "&'Общие данные'!C137&" va yashash maydoni - "&'Общие данные'!C140&" "&'Общие данные'!C133&", "&'Общие данные'!C130&" " -> Egalik huquqi 0ga tegishli bo'lgan umumiy maydoni - va yashash maydoni - 0,
A26: =IF('Общие данные'!B99='Общие данные'!C99,'Кредитная заявка'!A28:D28,IF('Общие данные'!B99='Общие данные'!D99,'Кредитная заявка'!A27:D27,0)) -> Egalik huquqi RO'ZIYEV ODILJON OLIMJONOVICHga tegishli bo'lgan garovga olingan avtomobil markasi SPARK, rangi - OQ BELAYA, ishlab chiqarilgan yili - 2018, davlat raqam belgisi 80F845XA, kuzov turi - YENGIL SEDAN, kuzov raqami XWBMF48NEJA525204, dvigatel raqami B15D212181062B8JX0417, shassi raqami - RAKAMSIZ
A27: =" Egalik huquqi "&'Общие данные'!B124&"ga tegishli bo'lgan "&'Общие данные'!B132&", "&'Общие данные'!B140&", davlat raqam belgisi "&'Общие данные'!B133&", "&'Общие данные'!B134&", "&'Общие данные'!B137&" avtotransport vositasi " -> Egalik huquqi RO'ZIYEV ODILJON OLIMJONOVICHga tegishli bo'lgan SPARK, rangi - OQ BELAYA, ishlab chiqarilgan yili - 2018, davlat raqam belgisi 80F845XA, kuzov turi - YENGIL SEDAN, kuzov raqami XWBMF48NEJA525204, dvigatel raqami B15D212181062B8JX0417, shassi raqami - RAKAMSIZ avtotransport vositasi
A28: =" Egalik huquqi "&'Общие данные'!B124&"ga tegishli bo'lgan garovga olingan avtomobil markasi "&'Общие данные'!B132&", "&'Общие данные'!B140&", davlat raqam belgisi "&'Общие данные'!B133&", "&'Общие данные'!B134&", "&'Общие данные'!B137&"" -> Egalik huquqi RO'ZIYEV ODILJON OLIMJONOVICHga tegishli bo'lgan garovga olingan avtomobil markasi SPARK, rangi - OQ BELAYA, ishlab chiqarilgan yili - 2018, davlat raqam belgisi 80F845XA, kuzov turi - YENGIL SEDAN, kuzov raqami XWBMF48NEJA525204, dvigatel raqami B15D212181062B8JX0417, shassi raqami - RAKAMSIZ
A29: ="2. «"&'Общие данные'!B154&"» АJ sug‘urta kompaniyasi tomonidan "&'Общие данные'!C64&" to'lamaslik xavfini "&FIXED('Общие данные'!B155,2)&"("&'Общие данные'!B156&") so ' m miqdoriga sug’urta qilish" -> 2. «АО СК "IMPEX INSURANCE"» АJ sug‘urta kompaniyasi tomonidan Mikroqarz to'lamaslik xavfini 23 800 000,00(yigirma uch million sakkiz yuz ming so'm) so ' m miqdoriga sug’urta qilish
A31: ="Mazkur ariza bilan "&'Общие данные'!B158&"ga men va soʻralayotgan "&'Общие данные'!B65&" boʻyicha barcha zarur maʼlumotlarni quyida ko’rsatilgan tashkilotlarga taqdim etish va olishga roziligimni bildirib, ushbu amaliyotlarni o’tkazish uchun huquq beraman:" -> Mazkur ariza bilan «PULLOL BUSINESS MIKROMOLIYA TASHKILOTI» MChJga men va soʻralayotgan mikroqarz boʻyicha barcha zarur maʼlumotlarni quyida ko’rsatilgan tashkilotlarga taqdim etish va olishga roziligimni bildirib, ushbu amaliyotlarni o’tkazish uchun huquq beraman:
A32: □ O‘zbekiston Respublikasi Markaziy banki huzuridagi kredit axborotining davlat reestri;
A33: □ Kredit-axborot tahliliy markazi «O‘zbekiston Respublikasi kredit byurosi» MChJ;
A34: □ Garov reestri taqdim etilgan garov mulki haqida.
A35: ="Ariza berilgan sana: "&TEXT('Общие данные'!B2,"ДД.ММ.ГГГГ")&"y." -> Ariza berilgan sana: 07.04.2026y.
A37: Ariza berilgan kuniga barcha ma'lumotlar ishonchligini tasdiqlab, ushbu arizani imzolayman
A40: ='Общие данные'!B5 -> ALLAMURODOV MUHAMMAD YOQUB O‘G‘LI | D40: ________________
D41: (imzo)
A43: ='Общие данные'!A171 -> Buxoro filiali boshlig’i | D43: ='Общие данные'!B171 -> Ikromov B.A.

Sheet Мажбуриятнома 
A3: MAJBURIYATNOMA
A4: =" Men, fuqaro "&'Общие данные'!B5&" "&'Общие данные'!B160&" bilan "&'Общие данные'!B69&" sanasidagi "&'Общие данные'!B66&"-sonli shartnomaning garov ta'minoti sifatida taqdim etilayotgan mulk "&'Общие данные'!B132&" rusumli avtotransport vositasini qonunga xilof ravishda o‘zlashtirmaslikka, yashirmaslikka, nobud qilmaslikka yoki unga shikast yetkazmaslik majburiyatini olaman." -> Men, fuqaro ALLAMURODOV MUHAMMAD YOQUB O‘G‘LI «PULLOL BUSINESS MIKROMOLIYA TASHKILOTI» MChJ bilan 7 aprel 2026 y. sanasidagi № 323-BR-sonli shartnomaning garov ta'minoti sifatida taqdim etilayotgan mulk SPARK rusumli avtotransport vositasini qonunga xilof ravishda o‘zlashtirmaslikka, yashirmaslikka, nobud qilmaslikka yoki unga shikast yetkazmaslik majburiyatini olaman.
A5: Ushbu majburiyatlarimni bajarmagan taqdirimda O'zbekiston Respublikasi jinoyat kodeksining 233-moddasi talablari asosida javobgarlik tog'risida ogohlantrildim.
A7: ='Общие данные'!B5 -> ALLAMURODOV MUHAMMAD YOQUB O‘G‘LI | B7: Imzo_____________
A9: ='Общие данные'!B5 -> ALLAMURODOV MUHAMMAD YOQUB O‘G‘LI | B9: Imzo_____________
A11: ="sana: "&TEXT('Общие данные'!B2,"ДД.ММ.ГГГГ")&" y." -> sana: 07.04.2026 y.

Sheet Заключение КК
A1: =""&'Общие данные'!B158&" mikromoliya tashkilotining Xulosasi" -> «PULLOL BUSINESS MIKROMOLIYA TASHKILOTI» MChJ mikromoliya tashkilotining Xulosasi
A3: MIJOZ HAQIDA MA'LUMOTLAR
A4: ="Mijozning to'liq ismi sharifi: "&'Общие данные'!B5&"" -> Mijozning to'liq ismi sharifi: ALLAMURODOV MUHAMMAD YOQUB O‘G‘LI
A5: ="Tug'ilgan sanasi: "&'Общие данные'!B15&"" -> Tug'ilgan sanasi: 24.05.1993 y
A6: ="Pasport seriyasi "&'Общие данные'!B16&" "&'Общие данные'!B20&", amal qilish muddati - "&'Общие данные'!B21&"" -> Pasport seriyasi AD 9213848 IIV 61013 tomonidan 31.10.2024 yilda berilgan, amal qilish muddati - 30.10.2034 y.
A7: ="Ro‘yxatdan o‘tgan manzili: "&'Общие данные'!B22&", mo'ljal: "&'Общие данные'!B26&"" -> Ro‘yxatdan o‘tgan manzili: BUXORO VILOYATI KOGON TUMANI SORG'UN MFY PARAKATI QQ 22-UY, mo'ljal: 7-MAKTAB
A8: ="Ish joyi: "&'Общие данные'!B52&" lavozimi "&'Общие данные'!B49&"da "&'Общие данные'!B44&" "&'Общие данные'!B47&"" -> Ish joyi: lavozimi Йўловчиларни енгил автотранспорт воситаларида ташишda O'Z O'ZINI BAND QILGAN FUQARO MA'LUMOTNOMA № № 0013114001
A10: ="Mijoz tomonidan so’ralgan "&'Общие данные'!B65&" shartlari:" -> Mijoz tomonidan so’ralgan mikroqarz shartlari:
A11: ='Кредитная заявка'!A13:D13 -> Mikroqarz summasi: 52 000 000,00 (ellik ikki million so'm) so'm.
A12: ='Кредитная заявка'!A14:D14 -> Mikroqarz muddati: 36 (O'ttiz olti ) oy.
A13: ='Кредитная заявка'!A15:D15 -> Mikroqarzdan foydalanganlik uchun foiz stavkasi: yillik 55% (Ellik besh ) foiz
A14: ='Кредитная заявка'!A16:D16 -> Mikroqarz bo'yicha asosiy qarz va foizlarni to'lash:
A15: ='Кредитная заявка'!A19:D19 -> - mikroqarz shartnomasi bo'yicha har oy differensial to'lovlari amalga oshiriladi
A16: ='Кредитная заявка'!A20:D20
A17: ='Кредитная заявка'!A21:D21 -> Mikroqarz ta’minoti::
A18: ='Кредитная заявка'!A22:D22 -> 1. Egalik huquqi RO'ZIYEV ODILJON OLIMJONOVICHga tegishli bo'lgan garovga olingan avtomobil markasi SPARK, rangi - OQ BELAYA, ishlab chiqarilgan yili - 2018, davlat raqam belgisi 80F845XA, kuzov turi - YENGIL SEDAN, kuzov raqami XWBMF48NEJA525204, dvigatel raqami B15D212181062B8JX0417, shassi raqami - RAKAMSIZ
A19: Mijozning moliyaviy holati
A20: ="Anketaga muvofiq "&'Общие данные'!B9&"ning o‘rtacha oylik daromadi "&FIXED('Анкета Клиента'!B27)&" so‘mni tashkil etdi." -> Anketaga muvofiq ALLAMURODOV M.Y.ning o‘rtacha oylik daromadi 13 000 000,00 so‘mni tashkil etdi.
A21: ="Mijozning o'rtacha oylik xarajatlari "&FIXED('Анкета Клиента'!F27)&" so'mni tashkil etdi" -> Mijozning o'rtacha oylik xarajatlari 1 800 000,00 so'mni tashkil etdi
A22: =IF('Общие данные'!B78='Общие данные'!C78,'Заключение КК'!A23:E23,'Заключение КК'!A24:E24) -> Mikroqarz shartnomasi bo'yicha birinchi oy uchun to'lov 3 806 012,04 so'mni tashkil etadi.
A23: =""&'Общие данные'!C64&" shartnomasi bo'yicha birinchi oy uchun to'lov "&FIXED('Общие данные'!B91)&" so'mni tashkil etadi." -> Mikroqarz shartnomasi bo'yicha birinchi oy uchun to'lov 3 806 012,04 so'mni tashkil etadi.
A24: =""&'Общие данные'!C64&" bo‘yicha oylik "&'Общие данные'!B78&" to‘lovi miqdori "&FIXED('Общие данные'!B91)&" so‘mni tashkil etadi." -> Mikroqarz bo‘yicha oylik differensial to‘lovi miqdori 3 806 012,04 so‘mni tashkil etadi.
A25: Mijoz quyidagi majburiyatlarga ega: "TOShKENT Sh., "ANOR BANK" АKTSIYADORLIK JАMIYATI 106 139 813.00 so'm, Ayni paytda muddati o'tgan qarzdorligi mavjud emas. O‘rtacha oylik to‘lov 5 353 870.46 so‘mni tashkil qiladi
A26: =""&'Общие данные'!C64&" bo’yicha ta’minot:" -> Mikroqarz bo’yicha ta’minot:
A27: =" - "&'Общие данные'!B124&" ga mulk huquqi asosida tegishli avtotransport vositasi "&'Общие данные'!B132&" , quyidagi tafsilotlarga muvofiq:" -> - RO'ZIYEV ODILJON OLIMJONOVICH ga mulk huquqi asosida tegishli avtotransport vositasi SPARK , quyidagi tafsilotlarga muvofiq:
A28: =" - "&'Общие данные'!C124&" ga mulk huquqi asosida tegishli ko'chmas mulk shaklida "&'Общие данные'!C133&", manzili: "&'Общие данные'!C130&", quyidagi tafsilotlarga muvofiq:" -> - 0 ga mulk huquqi asosida tegishli ko'chmas mulk shaklida 0, manzili: , quyidagi tafsilotlarga muvofiq:
A29: =IF('Общие данные'!B110="Avtotransport",'Заключение КК'!A27:E27,'Заключение КК'!A28:E28) -> - RO'ZIYEV ODILJON OLIMJONOVICH ga mulk huquqi asosida tegishli avtotransport vositasi SPARK , quyidagi tafsilotlarga muvofiq:
A30: ='Акт согласования'!A29 -> Nomi | B30: ='Акт согласования'!B29 -> Kuzov turi va kuzov raqami* | C30: ='Акт согласования'!C29 -> Dvigatel va shassi raqami* | D30: ='Акт согласования'!D29 -> Ishlab chiqarilgan yili va rangi* | E30: ='Акт согласования'!E29 -> Kelishilgan garov qiymati, so'm
A31: ='Акт согласования'!A30 -> SPARK | B31: ='Акт согласования'!B30 -> kuzov turi - YENGIL SEDAN, kuzov raqami XWBMF48NEJA525204 | C31: ='Акт согласования'!C30 -> dvigatel raqami B15D212181062B8JX0417, shassi raqami - RAKAMSIZ | D31: ='Акт согласования'!D30 -> rangi - OQ BELAYA, ishlab chiqarilgan yili - 2018 | E31: ='Акт согласования'!E30 -> 49 000 000,00 (qirq to'qqiz million so'm)
A32: ='Акт согласования'!A22 -> -* avtotransport egasi: RO'ZIYEV ODILJON OLIMJONOVICH
A33: ='Акт согласования'!A23 -> -* texnik pasport: AAG 2554881 10.10.2023 y
A34: ='Акт согласования'!A24 -> -* roʻyxatdan oʻtgan manzili/garaj manzili: BUXORO VILOYATI OLOT TUMANI ASAJAM MFY ASAJAM
A35: ='Акт согласования'!A25 -> -* davlat raqami: 80F845XA
A36: =""&'Общие данные'!B158&" mikromoliya tashkilotining Xulosasi" -> «PULLOL BUSINESS MIKROMOLIYA TASHKILOTI» MChJ mikromoliya tashkilotining Xulosasi
A37: =""&'Общие данные'!B158&" kredit qo‘mitasining xulosasiga quyidagi shartlarda "&'Общие данные'!B10&"ga "&'Общие данные'!B65&" berish masalasi kiritiladi:" -> «PULLOL BUSINESS MIKROMOLIYA TASHKILOTI» MChJ kredit qo‘mitasining xulosasiga quyidagi shartlarda ALLAMURODOV MUHAMMAD YOQUB O‘G‘LIga mikroqarz berish masalasi kiritiladi:
A38: =A11 -> Mikroqarz summasi: 52 000 000,00 (ellik ikki million so'm) so'm.
A39: =A12 -> Mikroqarz muddati: 36 (O'ttiz olti ) oy.
A40: =A13 -> Mikroqarzdan foydalanganlik uchun foiz stavkasi: yillik 55% (Ellik besh ) foiz
A41: =A14 -> Mikroqarz bo'yicha asosiy qarz va foizlarni to'lash:
A42: =A15 -> - mikroqarz shartnomasi bo'yicha har oy differensial to'lovlari amalga oshiriladi
...

Sheet договор
A1: =""&'Общие данные'!C64&" shartnoma "&'Общие данные'!B66&"" -> Mikroqarz shartnoma № 323-BR
A3: ="Toshkent shahri "&'Общие данные'!B70&"" -> Toshkent shahri 7 aprel 2026 y.
A5: =""&'Общие данные'!B158&", bundan buyon «Mikromoliya tashkiloti» deb nomlanuvchi, Nizom, Litsenziya va ishonchnoma asosida faoliyat yurituvchi "&'Общие данные'!A171&" "&'Общие данные'!B171&" bir tomondan va o‘z manfaati yo‘lida hamda o‘z nomidan harakat qiluvchi O‘zbekiston Respublikasi fuqarosi "&'Общие данные'!B5&" (pasport raqami "&'Общие данные'!B16&", "&'Общие данные'!C20&" ), bundan buyon «Qarz oluvchi» deb nomlanuvchi, boshqa tomondan, birgalikda “Tomonlar” yoki alohida “Tomon” deb nomlanuvchilar, Qarz oluvchi tomonidan "&TEXT('Общие данные'!B2,"ДД.ММ.ГГГГ")&" yil,"&'Общие данные'!B65&" olish uchun ariza berilganligini hisobga olib, ushbu "&'Общие данные'!C64&" shartnomasini (bundan keyin – «Shartnoma») quyidagilar haqida tuzdilar:" -> «PULLOL BUSINESS MIKROMOLIYA TASHKILOTI» MChJ, bundan buyon «Mikromoliya tashkiloti» deb nomlanuvchi, Nizom, Litsenziya va ishonchnoma asosida faoliyat yurituvchi Buxoro filiali boshlig’i Ikromov B.A. bir tomondan va o‘z manfaati yo‘lida hamda o‘z nomidan harakat qiluvchi O‘zbekiston Respublikasi fuqarosi ALLAMURODOV MUHAMMAD YOQUB O‘G‘LI (pasport raqami AD 9213848 , IIV 61013 tomonidan 31.10.2024 yilda berilgan ), bundan buyon «Qarz oluvchi» deb nomlanuvchi, boshqa tomondan, birgalikda “Tomonlar” yoki alohida “Tomon” deb nomlanuvchilar, Qarz oluvchi tomonidan 07.04.2026 yil,mikroqarz olish uchun ariza berilganligini hisobga olib, ushbu Mikroqarz shartnomasini (bundan keyin – «Shartnoma») quyidagilar haqida tuzdilar:
A7: 1. SHARTNOMA PREDMETI
A8: ="1.1. Mikromoliya tashkiloti Qarz oluvchiga umumiy miqdori "&FIXED('Общие данные'!B76,2)&" ("&'Общие данные'!C77&") bo‘lgan "&'Общие данные'!B65&"ni "&'Общие данные'!B71&" dan "&'Общие данные'!B73&" gacha bo'lgan muddatga naqd pul va/yoki o'tkazmasi shaklida ajratadi." -> 1.1. Mikromoliya tashkiloti Qarz oluvchiga umumiy miqdori 52 000 000,00 (Ellik ikki million so'm) bo‘lgan mikroqarzni 7 aprel 2026 y. dan 7 aprel 2029 y. gacha bo'lgan muddatga naqd pul va/yoki o'tkazmasi shaklida ajratadi.
A9: ="1.2. Qarz oluvchi to‘lovlilik, muddatlilik va ta’minlanganlik tamoyillariga amal qilgan holda "&'Общие данные'!B65&"dan foydalanish majburiyatini o‘z zimmasiga oladi." -> 1.2. Qarz oluvchi to‘lovlilik, muddatlilik va ta’minlanganlik tamoyillariga amal qilgan holda mikroqarzdan foydalanish majburiyatini o‘z zimmasiga oladi.
A11: ="2. "&'Общие данные'!D64&" BERISH VA QAYTARISH TARTIBI" -> 2. MIKROQARZ BERISH VA QAYTARISH TARTIBI
A12: ="2.1. Ushbu Shartnomaning 1.1.-bandida ko‘rsatilgan summa miqdoridagi "&'Общие данные'!B65&" Mikromoliya tashkiloti kassasidan naqd pul shaklida va/yoki plastik kartaga o‘tkazish yuli bilan beriladi." -> 2.1. Ushbu Shartnomaning 1.1.-bandida ko‘rsatilgan summa miqdoridagi mikroqarz Mikromoliya tashkiloti kassasidan naqd pul shaklida va/yoki plastik kartaga o‘tkazish yuli bilan beriladi.
A13: ="2.2. "&'Общие данные'!C64&" berish ushbu Shartnoma tuzilgan va Qarz oluvchi tomonidan ushbu shartnomaning 3-bo‘limiga muvofiq garov ta'minoti ta'minlangandan so‘ng 10 kalendar kundan kechiktirmay amalga oshiriladi." -> 2.2. Mikroqarz berish ushbu Shartnoma tuzilgan va Qarz oluvchi tomonidan ushbu shartnomaning 3-bo‘limiga muvofiq garov ta'minoti ta'minlangandan so‘ng 10 kalendar kundan kechiktirmay amalga oshiriladi.
A14: ="2.3. "&'Общие данные'!C64&" Qarz oluvchi tomonidan ushbu Shartnomaning ajralmas qismi hisoblanadigan 1-ilovasida ko‘rsatilgan to‘lov jadvalida (bundan keyin - To‘lov jadvali) belgilangan miqdor, tartib va muddatlarda qaytariladi." -> 2.3. Mikroqarz Qarz oluvchi tomonidan ushbu Shartnomaning ajralmas qismi hisoblanadigan 1-ilovasida ko‘rsatilgan to‘lov jadvalida (bundan keyin - To‘lov jadvali) belgilangan miqdor, tartib va muddatlarda qaytariladi.
A15: ="2.4. Mikromoliya tashkiloti, "&'Общие данные'!B65&" berilgan vaqtdan boshlab, "&'Общие данные'!B65&" miqdorining qoldiq summasiga "&'Общие данные'!B86&"% ("&'Общие данные'!C87&") foiz yillik va yiliga 365/366 kunlik hisobidan foizlar hisoblaydi. To'lov jadvaliga muvofiq asosiy qarz bo'yicha navbatdagi to'lov buzilgan hollarda, "&"foiz stavkasi oshiriladi va Mikromoliya tashkiloti "&'Общие данные'!B65&"ning muddati o'tgan asosiy qarz summasiga yillik "&'Общие данные'!B89&"% ("&'Общие данные'!B90&") foiz miqdorida foizlar hisoblaydi____________________." -> 2.4. Mikromoliya tashkiloti, mikroqarz berilgan vaqtdan boshlab, mikroqarz miqdorining qoldiq summasiga 55% (Ellik besh ) foiz yillik va yiliga 365/366 kunlik hisobidan foizlar hisoblaydi. To'lov jadvaliga muvofiq asosiy qarz bo'yicha navbatdagi to'lov buzilgan hollarda, foiz stavkasi oshiriladi va Mikromoliya tashkiloti mikroqarzning muddati o'tgan asosiy qarz summasiga yillik 155% (bir yuz ellik besh) foiz miqdorida foizlar hisoblaydi____________________.
A16: 2.4.1 Qarz oluvchining xisob raqamlaridan shartnomaning 4.1.2 bandida ko‘rsatilgan tartibda yechib olingan pul mablag‘lari yechib olinganidan so‘ng mijoz tomonidan kredit qarzdorligini so‘ndirish uchun bank kassalari orqali to‘langan pul mablag‘lari yoki mijoz tomonidan kredit qarzdorligini so‘ndirish uchun bank kassalari orqali to‘langandan so‘ng qarz oluvchining xisob raqamlaridan shartnomaning 4.1.2 bandida ko‘rsatilgan tartibda yechib olingan pul mablag‘larining bir oylik kredit to‘lovini so‘ndirishga yo‘naltirilgan miqdoridan ortiqcha qismi qarz oluvchining to‘lov amalga oshirilgan kundan boshlab 3 bank ish kuni ichida yo‘llagan arizasiga asosan qarz oluvchiga qaytarilishi mumkun. 2.5. Foizlar To‘lov jadvaliga muvofiq asosiy qarzni qaytarish uchun belgilangan sanada to‘lanadi. 2.5.1 Qarz oluvchi tomonidan shartnomaning 2.4 bandida ko‘rsatilgan muddatda ortiqcha to‘langan pul mablag‘larini qaytarish to‘g‘risida ariza berilmagan taqdirda to‘langan ortiqcha pul mablag‘lari mijozning asosiy qarzdorligini so‘ndirishga yo‘naltiriladi.
A17: =CONCATENATE(C17,H17,I17) -> 2.6 Qarz oluvchi tomonidan to‘lov jadvalida ko‘rsatilgan muddatdan oldin xamda to‘lov jadvalida ko‘rsatilgan oylik kredit qarzdorligini so‘ndirish miqdoridan ko‘p miqdorda to‘lovni amalga oshirib, to‘langan pul mablag‘larini asosiy kredit qarzdorligini so‘ndirishga yo‘naltirilishini so‘ralganda qarz oluvchining kredit qarzdorligini so‘ndirish uchun to‘lagan pul mablag‘laridan kredit qarzdorligi to‘langan oy uchun to‘lov jadvali bo‘yicha so‘ndirilishi lozim bo‘lgan foiz qarzdorligi summasi, to‘lov jadvalida foiz qarzdorligi so‘ndirilishi ko‘rsatilgan muddatga qadar tashkilotning xisob raqamida saqlanib to‘lov jadvalida ko‘rsatilgan sanada oylik foiz qarzdorligini so‘ndirishga yo‘naltiriladi. 2.6.1. Qarz oluvchi tomonidan olingan mikroqarzni va undan foydalanganlik uchun foizlarni qaytarish bo‘yicha muddati o‘tgan qarzdorlik hosil bo‘lganda Qarz oluvchi tomonidan ko‘rsatilgan qarzdorlikni to‘lash hisobiga to‘lanadigan summalar quyidagi tartibda hisobga olinadi: | C17: 2.6 Qarz oluvchi tomonidan to‘lov jadvalida ko‘rsatilgan muddatdan oldin xamda to‘lov jadvalida ko‘rsatilgan oylik kredit qarzdorligini so‘ndirish miqdoridan ko‘p miqdorda to‘lovni amalga oshirib, to‘langan pul mablag‘larini asosiy kredit qarzdorligini so‘ndirishga yo‘naltirilishini so‘ralganda qarz oluvchining kredit qarzdorligini so‘ndirish uchun to‘lagan pul mablag‘laridan kredit qarzdorligi to‘langan oy uchun to‘lov jadvali bo‘yicha so‘ndirilishi lozim bo‘lgan foiz qarzdorligi summasi, to‘lov jadvalida foiz qarzdorligi so‘ndirilishi ko‘rsatilgan muddatga qadar tashkilotning xisob raqamida saqlanib to‘lov jadvalida ko‘rsatilgan sanada oylik foiz qarzdorligini so‘ndirishga yo‘naltiriladi. 2.6.1. Qarz oluvchi tomonidan olingan | H17: ='Общие данные'!B65 -> mikroqarz | I17: ni va undan foydalanganlik uchun foizlarni qaytarish bo‘yicha muddati o‘tgan qarzdorlik hosil bo‘lganda Qarz oluvchi tomonidan ko‘rsatilgan qarzdorlikni to‘lash hisobiga to‘lanadigan summalar quyidagi tartibda hisobga olinadi:
A18: - jarima sanksiyalarni to‘lash; - to‘lov muddati o‘tgan foizlarni to‘lash; - to‘lov muddati o‘tgan asosiy qarzni to‘lash; - muddatli qarz bo‘yicha hisoblangan foizlarni to‘lash; - muddatli asosiy qarzni to‘lash; - Mikromoliya tashkilotning boshqa zararlarini qoplash.
A19: ="2.7. Qarz oluvchi Mikromoliya tashkilotining "&'Общие данные'!B65&" bo‘yicha asosiy summasi, hisoblangan foizlarni, penya va boshqa moliyaviy talablarini ham naqd pul shaklida, ham naqdsiz shaklda qaytarib beradi." -> 2.7. Qarz oluvchi Mikromoliya tashkilotining mikroqarz bo‘yicha asosiy summasi, hisoblangan foizlarni, penya va boshqa moliyaviy talablarini ham naqd pul shaklida, ham naqdsiz shaklda qaytarib beradi.
A20: ="2.8. Qarz oluvchi "&'Общие данные'!B65&" miqdorini muddatidan oldin qaytarish, shuningdek, bu haqida Mikromoliya tashkilotini albatta ogohlantirgan holda ulardan aniq foydalangan muddat uchun hisoblangan foizlarni to‘lash huquqiga ega." -> 2.8. Qarz oluvchi mikroqarz miqdorini muddatidan oldin qaytarish, shuningdek, bu haqida Mikromoliya tashkilotini albatta ogohlantirgan holda ulardan aniq foydalangan muddat uchun hisoblangan foizlarni to‘lash huquqiga ega.
A21: =CONCATENATE(C21,H21,I21) -> 2.9. Qarz oluvchi jismoniy shaxslarning kreditlar (mikroqarzlar) bo‘yicha qarz yukini hisoblash tartibi, qarz yukining ruxsat etilgan miqdori, shuningdek qarz yuki o‘sishini cheklash to‘g‘risidagi Nizomga muvofiq (O’zbekiston Respublikasi Adliya vazirligi tomonidan 19.12.2019 y. 3205-son bilan ro‘yxatga olingan Markaziy bank Boshqaruvining 28.09.2019 y. 24/5-son qarori bilan tasdiqlangan), qarz yuki ko‘rsatkichi har bir qarz oluvchiga qarz beruvchi tomonidan mikroqarz ajratishda uning summasi va qarz oluvchining amaldagi kredit (mikroqarz) shartnomalari bo‘yicha asosiy qarz qoldig‘i yig‘indisi bazaviy hisoblash miqdorining 50 baravaridan oshganda hisoblanadi. | C21: ="2.9. Qarz oluvchi jismoniy shaxslarning kreditlar ("&'Общие данные'!B65&"lar) bo‘yicha qarz yukini hisoblash tartibi, qarz yukining ruxsat etilgan miqdori, shuningdek qarz yuki o‘sishini cheklash to‘g‘risidagi Nizomga muvofiq (O’zbekiston Respublikasi Adliya vazirligi tomonidan 19.12.2019 y. 3205-son bilan ro‘yxatga " -> 2.9. Qarz oluvchi jismoniy shaxslarning kreditlar (mikroqarzlar) bo‘yicha qarz yukini hisoblash tartibi, qarz yukining ruxsat etilgan miqdori, shuningdek qarz yuki o‘sishini cheklash to‘g‘risidagi Nizomga muvofiq (O’zbekiston Respublikasi Adliya vazirligi tomonidan 19.12.2019 y. 3205-son bilan ro‘yxatga | H21: ="olingan Markaziy bank Boshqaruvining 28.09.2019 y. 24/5-son qarori bilan tasdiqlangan), qarz yuki ko‘rsatkichi har bir qarz oluvchiga qarz beruvchi tomonidan "&'Общие данные'!B65&" ajratishda uning summasi va " -> olingan Markaziy bank Boshqaruvining 28.09.2019 y. 24/5-son qarori bilan tasdiqlangan), qarz yuki ko‘rsatkichi har bir qarz oluvchiga qarz beruvchi tomonidan mikroqarz ajratishda uning summasi va | I21: ="qarz oluvchining amaldagi kredit ("&'Общие данные'!B65&") shartnomalari bo‘yicha asosiy qarz qoldig‘i yig‘indisi bazaviy hisoblash miqdorining 50 baravaridan oshganda hisoblanadi." -> qarz oluvchining amaldagi kredit (mikroqarz) shartnomalari bo‘yicha asosiy qarz qoldig‘i yig‘indisi bazaviy hisoblash miqdorining 50 baravaridan oshganda hisoblanadi.
A22: ="3. "&'Общие данные'!D64&" TA'MINOTI BO‘YICHA " -> 3. MIKROQARZ TA'MINOTI BO‘YICHA
A23: ="3.1. Ushbu Shartnoma bo‘yicha taqdim etilgan "&'Общие данные'!C64&" quyidagi "&'Общие данные'!C64&" summasiga nisbatan 140% dan kam bo'lmagan, yani birgalikdagi jami qiymati "&FIXED('Общие данные'!C75,2)&" ("&'Общие данные'!D75&") so'm miqdorida bo'lgan garov va "&'Общие данные'!C64&" to'lamaslik xavfini sug'urta polisi bilan ta'minlanadi:" -> 3.1. Ushbu Shartnoma bo‘yicha taqdim etilgan Mikroqarz quyidagi Mikroqarz summasiga nisbatan 140% dan kam bo'lmagan, yani birgalikdagi jami qiymati 72 800 000,00 (yetmish ikki million sakkiz yuz ming so'm) so'm miqdorida bo'lgan garov va Mikroqarz to'lamaslik xavfini sug'urta polisi bilan ta'minlanadi:
A24: =IF('Общие данные'!B110='Общие данные'!C110,договор!A28,IF('Общие данные'!B110='Общие данные'!D110,договор!A25,0)) -> 3.1.1. Mikromoliya tashkiloti, Qarz oluvchi va ALLAMURODOV ALISHER YOQUBOVICH (07.04.2026 yy. sanasidagi reestr raqami №202602372001231 bo'lgan Ishonchnomaga asosan) tomonidan 2026 yil 7 aprelda imzolangan 1-sonli garov predmeti qiymatini tasdiqlash dalolatnomasiga muvofiq OQ BELAYA rangli, ishlab chiqarilgan yili – 2018 yil, dvigatel raqami B15D212181062B8JX0417, shassi - RAKAMSIZ, kuzov turi - YENGIL SEDAN, kuzov raqami №XWBMF48NEJA525204, davlat raqam belgisi 80F845XA bo'lgan SPARK rusumli avtomashinasi (bundan keyin “Garov predmeti”), egalik huquqiga ega RO'ZIYEV ODILJON OLIMJONOVICHga tegishli va kelishilgan garov qiymati 2026 yil 7 aprelda imzolangan 1-sonli Garov predmeti qiymatini tasdiqlash dalolatnomasiga muvifiq 49 000 000,00 (qirq to'qqiz million so'm) so'mni tashkil qiladi. Garov garovining aniq shartlari tegishli notarial rasmiylashtirilgan garov shartnomasi bilan belgilanadi.
A25: =IF('Общие данные'!B99='Общие данные'!C99,договор!A27,IF('Общие данные'!B99='Общие данные'!D99,договор!A26,0)) -> 3.1.1. Mikromoliya tashkiloti, Qarz oluvchi va ALLAMURODOV ALISHER YOQUBOVICH (07.04.2026 yy. sanasidagi reestr raqami №202602372001231 bo'lgan Ishonchnomaga asosan) tomonidan 2026 yil 7 aprelda imzolangan 1-sonli Garov predmeti qiymatini tasdiqlash dalolatnomasiga muvofiq manzilida joylashgan, 0 bo'lgan, 0 ko'rinishidagi ko'chmas mulk (bundan keyin “Garov predmeti”), egalik huquqiga ko'ra 0ga tegishli va kelishilgan garov qiymati 2026 yil 7 aprelda imzolangan 1-sonli Garov predmeti qiymatini tasdiqlash dalolatnomasiga muvofiq 49 000 000,00 (qirq to'qqiz million so'm) so'mni tashkil qiladi. Garovning aniq shartlari tegishli tarzda notarial tasdiqlangan garov shartnomasi bilan belgilangan.
A26: ="3.1.1. "&'Общие данные'!N133&" tomonidan "&'Общие данные'!B150&" yil "&'Общие данные'!B152&" "&'Общие данные'!B151&"da imzolangan 1-sonli navbatdagi garov predmeti qiymatini tasdiqlash dalolatnomasiga muvofiq "&'Общие данные'!C130&" manzilida joylashgan, "&'Общие данные'!E133&" bo'lgan, "&'Общие данные'!E132&" ko'rinishidagi ko'chmas mulk (bundan keyin “navbatdagi garov predmeti”), egalik huquqiga ko'ra "&'Общие данные'!C124&"ga tegishli va kelishilgan garov qiymati "&'Общие данные'!B150&" yil "&'Общие данные'!B152&" "&'Общие данные'!B151&"da imzolangan 1-sonli Garov predmeti qiymatini tasdiqlash dalolatnomasiga muvofiq "&FIXED('Общие данные'!B143,2)&" ("&'Общие данные'!B145&") so'mni tashkil qiladi. Garovning aniq shartlari tegishli tarzda notarial tasdiqlangan garov shartnomasi bilan belgilangan." -> 3.1.1. Mikromoliya tashkiloti, Qarz oluvchi va ALLAMURODOV ALISHER YOQUBOVICH (07.04.2026 yy. sanasidagi reestr raqami №202602372001231 bo'lgan Ishonchnomaga asosan) tomonidan 2026 yil 7 aprelda imzolangan 1-sonli navbatdagi garov predmeti qiymatini tasdiqlash dalolatnomasiga muvofiq manzilida joylashgan, 0 bo'lgan, 0 ko'rinishidagi ko'chmas mulk (bundan keyin “navbatdagi garov predmeti”), egalik huquqiga ko'ra 0ga tegishli va kelishilgan garov qiymati 2026 yil 7 aprelda imzolangan 1-sonli Garov predmeti qiymatini tasdiqlash dalolatnomasiga muvofiq 49 000 000,00 (qirq to'qqiz million so'm) so'mni tashkil qiladi. Garovning aniq shartlari tegishli tarzda notarial tasdiqlangan garov shartnomasi bilan belgilangan.
A27: ="3.1.1. "&'Общие данные'!N133&" tomonidan "&'Общие данные'!B150&" yil "&'Общие данные'!B152&" "&'Общие данные'!B151&"da imzolangan 1-sonli Garov predmeti qiymatini tasdiqlash dalolatnomasiga muvofiq "&'Общие данные'!C130&" manzilida joylashgan, "&'Общие данные'!E133&" bo'lgan, "&'Общие данные'!E132&" ko'rinishidagi ko'chmas mulk (bundan keyin “Garov predmeti”), egalik huquqiga ko'ra "&'Общие данные'!C124&"ga tegishli va kelishilgan garov qiymati "&'Общие данные'!B150&" yil "&'Общие данные'!B152&" "&'Общие данные'!B151&"da imzolangan 1-sonli Garov predmeti qiymatini tasdiqlash dalolatnomasiga muvofiq "&FIXED('Общие данные'!B143,2)&" ("&'Общие данные'!B145&") so'mni tashkil qiladi. Garovning aniq shartlari tegishli tarzda notarial tasdiqlangan garov shartnomasi bilan belgilangan." -> 3.1.1. Mikromoliya tashkiloti, Qarz oluvchi va ALLAMURODOV ALISHER YOQUBOVICH (07.04.2026 yy. sanasidagi reestr raqami №202602372001231 bo'lgan Ishonchnomaga asosan) tomonidan 2026 yil 7 aprelda imzolangan 1-sonli Garov predmeti qiymatini tasdiqlash dalolatnomasiga muvofiq manzilida joylashgan, 0 bo'lgan, 0 ko'rinishidagi ko'chmas mulk (bundan keyin “Garov predmeti”), egalik huquqiga ko'ra 0ga tegishli va kelishilgan garov qiymati 2026 yil 7 aprelda imzolangan 1-sonli Garov predmeti qiymatini tasdiqlash dalolatnomasiga muvofiq 49 000 000,00 (qirq to'qqiz million so'm) so'mni tashkil qiladi. Garovning aniq shartlari tegishli tarzda notarial tasdiqlangan garov shartnomasi bilan belgilangan.
A28: =IF('Общие данные'!B99='Общие данные'!C99,A29,IF('Общие данные'!B99='Общие данные'!D99,A30,0)) -> 3.1.1. Mikromoliya tashkiloti, Qarz oluvchi va ALLAMURODOV ALISHER YOQUBOVICH (07.04.2026 yy. sanasidagi reestr raqami №202602372001231 bo'lgan Ishonchnomaga asosan) tomonidan 2026 yil 7 aprelda imzolangan 1-sonli garov predmeti qiymatini tasdiqlash dalolatnomasiga muvofiq OQ BELAYA rangli, ishlab chiqarilgan yili – 2018 yil, dvigatel raqami B15D212181062B8JX0417, shassi - RAKAMSIZ, kuzov turi - YENGIL SEDAN, kuzov raqami №XWBMF48NEJA525204, davlat raqam belgisi 80F845XA bo'lgan SPARK rusumli avtomashinasi (bundan keyin “Garov predmeti”), egalik huquqiga ega RO'ZIYEV ODILJON OLIMJONOVICHga tegishli va kelishilgan garov qiymati 2026 yil 7 aprelda imzolangan 1-sonli Garov predmeti qiymatini tasdiqlash dalolatnomasiga muvifiq 49 000 000,00 (qirq to'qqiz million so'm) so'mni tashkil qiladi. Garov garovining aniq shartlari tegishli notarial rasmiylashtirilgan garov shartnomasi bilan belgilanadi.
A29: ="3.1.1. "&'Общие данные'!N133&" tomonidan "&'Общие данные'!B150&" yil "&'Общие данные'!B152&" "&'Общие данные'!B151&"da imzolangan 1-sonli garov predmeti qiymatini tasdiqlash dalolatnomasiga muvofiq "&'Общие данные'!B141&" rangli, ishlab chiqarilgan yili – "&'Общие данные'!B142&" yil, dvigatel raqami "&'Общие данные'!B138&", shassi - "&'Общие данные'!B139&", kuzov turi - "&'Общие данные'!B135&", kuzov raqami №"&'Общие данные'!B136&", davlat raqam belgisi "&'Общие данные'!B133&" bo'lgan "&'Общие данные'!B132&" rusumli avtomashinasi (bundan keyin “Garov predmeti”), egalik huquqiga ega "&'Общие данные'!B124&"ga tegishli va kelishilgan garov qiymati "&'Общие данные'!B150&" yil "&'Общие данные'!B152&" "&'Общие данные'!B151&"da imzolangan 1-sonli Garov predmeti qiymatini tasdiqlash dalolatnomasiga muvifiq "&FIXED('Общие данные'!B143,2)&" ("&'Общие данные'!B145&") so'mni tashkil qiladi. Garov garovining aniq shartlari tegishli notarial rasmiylashtirilgan garov shartnomasi bilan belgilanadi." -> 3.1.1. Mikromoliya tashkiloti, Qarz oluvchi va ALLAMURODOV ALISHER YOQUBOVICH (07.04.2026 yy. sanasidagi reestr raqami №202602372001231 bo'lgan Ishonchnomaga asosan) tomonidan 2026 yil 7 aprelda imzolangan 1-sonli garov predmeti qiymatini tasdiqlash dalolatnomasiga muvofiq OQ BELAYA rangli, ishlab chiqarilgan yili – 2018 yil, dvigatel raqami B15D212181062B8JX0417, shassi - RAKAMSIZ, kuzov turi - YENGIL SEDAN, kuzov raqami №XWBMF48NEJA525204, davlat raqam belgisi 80F845XA bo'lgan SPARK rusumli avtomashinasi (bundan keyin “Garov predmeti”), egalik huquqiga ega RO'ZIYEV ODILJON OLIMJONOVICHga tegishli va kelishilgan garov qiymati 2026 yil 7 aprelda imzolangan 1-sonli Garov predmeti qiymatini tasdiqlash dalolatnomasiga muvifiq 49 000 000,00 (qirq to'qqiz million so'm) so'mni tashkil qiladi. Garov garovining aniq shartlari tegishli notarial rasmiylashtirilgan garov shartnomasi bilan belgilanadi.
A30: ="3.1.1. "&'Общие данные'!N133&" tomonidan "&'Общие данные'!B150&" yil "&'Общие данные'!B152&" "&'Общие данные'!B151&"da imzolangan 1-sonli navbatdagi garov predmeti qiymatini tasdiqlash dalolatnomasiga muvofiq "&'Общие данные'!B141&" rangli, ishlab chiqarilgan yili – "&'Общие данные'!B142&" yil, dvigatel raqami "&'Общие данные'!B138&", shassi - "&'Общие данные'!B139&", kuzov turi - "&'Общие данные'!B135&", kuzov raqami №"&'Общие данные'!B136&", davlat raqam belgisi "&'Общие данные'!B133&" bo'lgan "&'Общие данные'!B132&" rusumli avtomashinasi (bundan keyin “navbatdagi garov predmeti”), egalik huquqiga ega "&'Общие данные'!B124&"ga tegishli va kelishilgan garov qiymati "&'Общие данные'!B150&" yil "&'Общие данные'!B152&" "&'Общие данные'!B151&"da imzolangan 1-sonli Garov predmeti qiymatini tasdiqlash dalolatnomasiga muvifiq "&FIXED('Общие данные'!B143,2)&" ("&'Общие данные'!B145&") so'mni tashkil qiladi. Garov garovining aniq shartlari tegishli notarial rasmiylashtirilgan garov shartnomasi bilan belgilanadi." -> 3.1.1. Mikromoliya tashkiloti, Qarz oluvchi va ALLAMURODOV ALISHER YOQUBOVICH (07.04.2026 yy. sanasidagi reestr raqami №202602372001231 bo'lgan Ishonchnomaga asosan) tomonidan 2026 yil 7 aprelda imzolangan 1-sonli navbatdagi garov predmeti qiymatini tasdiqlash dalolatnomasiga muvofiq OQ BELAYA rangli, ishlab chiqarilgan yili – 2018 yil, dvigatel raqami B15D212181062B8JX0417, shassi - RAKAMSIZ, kuzov turi - YENGIL SEDAN, kuzov raqami №XWBMF48NEJA525204, davlat raqam belgisi 80F845XA bo'lgan SPARK rusumli avtomashinasi (bundan keyin “navbatdagi garov predmeti”), egalik huquqiga ega RO'ZIYEV ODILJON OLIMJONOVICHga tegishli va kelishilgan garov qiymati 2026 yil 7 aprelda imzolangan 1-sonli Garov predmeti qiymatini tasdiqlash dalolatnomasiga muvifiq 49 000 000,00 (qirq to'qqiz million so'm) so'mni tashkil qiladi. Garov garovining aniq shartlari tegishli notarial rasmiylashtirilgan garov shartnomasi bilan belgilanadi.
A31: =CONCATENATE(C31,D31) -> 3.1.2. «АО СК "IMPEX INSURANCE"» АJ sug‘urta kompaniyasi (keyingi o'rinlarda-Sug‘urtalovchi) tomonidan Mikroqarz to'lamaslik xavfini Mikroqarz summasiga nisbatan 140% dan hisoblab 23 800 000,00(yigirma uch million sakkiz yuz ming so'm) so ' m miqdoriga sug’urta qilish. Ushbu shartnoma bo‘yicha Mikroqarz berilgunga qadar Mikromoliya tashkiloti Sug‘urtalovchi 23 800 000,00(yigirma uch million sakkiz yuz ming so'm) so ' m miqdoridagi Mikroqarzni to‘lamaslik xavfini sug‘urta qilish shartnomasini tuzadi va Sug‘urtalovchi nomiga sug‘urta mukofotini to‘laydi, Qarz oluvchi esa Mikromoliya tashkiloti tomonidan sug‘urta mukofotini to‘langan kuni Mikromoliya tashkiloti tomonidan to‘langan sug‘urta mukofotini Mikromoliya tashkilotiga to‘laydi." | C31: ="3.1.2. «"&'Общие данные'!B154&"» АJ sug‘urta kompaniyasi (keyingi o'rinlarda-Sug‘urtalovchi) tomonidan "&'Общие данные'!C64&" to'lamaslik xavfini "&'Общие данные'!C64&" summasiga nisbatan 140% dan hisoblab "&FIXED('Общие данные'!B155,2)&"("&'Общие данные'!B156&") so ' m miqdoriga sug’urta qilish." -> 3.1.2. «АО СК "IMPEX INSURANCE"» АJ sug‘urta kompaniyasi (keyingi o'rinlarda-Sug‘urtalovchi) tomonidan Mikroqarz to'lamaslik xavfini Mikroqarz summasiga nisbatan 140% dan hisoblab 23 800 000,00(yigirma uch million sakkiz yuz ming so'm) so ' m miqdoriga sug’urta qilish. | D31: =CONCATENATE(E31,F31) -> Ushbu shartnoma bo‘yicha Mikroqarz berilgunga qadar Mikromoliya tashkiloti Sug‘urtalovchi 23 800 000,00(yigirma uch million sakkiz yuz ming so'm) so ' m miqdoridagi Mikroqarzni to‘lamaslik xavfini sug‘urta qilish shartnomasini tuzadi va Sug‘urtalovchi nomiga sug‘urta mukofotini to‘laydi, Qarz oluvchi esa Mikromoliya tashkiloti tomonidan sug‘urta mukofotini to‘langan kuni Mikromoliya tashkiloti tomonidan to‘langan sug‘urta mukofotini Mikromoliya tashkilotiga to‘laydi." | E31: =" Ushbu shartnoma bo‘yicha "&'Общие данные'!C64&" berilgunga qadar Mikromoliya tashkiloti Sug‘urtalovchi "&FIXED('Общие данные'!B155,2)&"("&'Общие данные'!B156&") so ' m miqdoridagi "&'Общие данные'!C64&"" -> Ushbu shartnoma bo‘yicha Mikroqarz berilgunga qadar Mikromoliya tashkiloti Sug‘urtalovchi 23 800 000,00(yigirma uch million sakkiz yuz ming so'm) so ' m miqdoridagi Mikroqarz | F31: ni to‘lamaslik xavfini sug‘urta qilish shartnomasini tuzadi va Sug‘urtalovchi nomiga sug‘urta mukofotini to‘laydi, Qarz oluvchi esa Mikromoliya tashkiloti tomonidan sug‘urta mukofotini to‘langan kuni Mikromoliya tashkiloti tomonidan to‘langan sug‘urta mukofotini Mikromoliya tashkilotiga to‘laydi."
A32: =CONCATENATE(A33,B33) -> 3.2. Qonun hujjatlariga muvofiq rasmiylashtirilgan, “Garov predmeti” hisoblangan notarial tasdiqlangan garov shartnomasi, shu jumladan “Garov predmeti”ga taʼqiq quyilganligi tasdiqlovchi xujjat Qarz oluvchi tomonidan ushbu shartnoma tuzilgandan so‘ng 10 bank kuni mobaynida Mikromoliya tashkilotiga taqdim etilishi lozim. Garov shartnomasi belgilangan muddatda taqdim etilmagan hollarda, Mikromoliya tashkiloti Qarz oluvchining manziliga yozma bildirishnoma yuborish orqali mikroqarz berishni rad etish va / yoki ushbu shartnomani bir tomonlama bekor qilish huquqiga egadir. Bunda ushbu shartnoma Qarz oluvchi tomonidan talabnoma olingan vaqtda yoki talabnoma pochta xizmati orqali yuborilgandan keyin uchinchi kuni bekor qilingan hisoblanadi.
A33: 3.2. Qonun hujjatlariga muvofiq rasmiylashtirilgan, “Garov predmeti” hisoblangan notarial tasdiqlangan garov shartnomasi, shu jumladan “Garov predmeti”ga taʼqiq quyilganligi tasdiqlovchi xujjat Qarz oluvchi tomonidan ushbu shartnoma tuzilgandan so‘ng 10 bank kuni mobaynida | B33: =CONCATENATE(A34,B34) -> Mikromoliya tashkilotiga taqdim etilishi lozim. Garov shartnomasi belgilangan muddatda taqdim etilmagan hollarda, Mikromoliya tashkiloti Qarz oluvchining manziliga yozma bildirishnoma yuborish orqali mikroqarz berishni rad etish va / yoki ushbu shartnomani bir tomonlama bekor qilish huquqiga egadir. Bunda ushbu shartnoma Qarz oluvchi tomonidan talabnoma olingan vaqtda yoki talabnoma pochta xizmati orqali yuborilgandan keyin uchinchi kuni bekor qilingan hisoblanadi.
A34: =" Mikromoliya tashkilotiga taqdim etilishi lozim. Garov shartnomasi belgilangan muddatda taqdim etilmagan hollarda, Mikromoliya tashkiloti Qarz oluvchining manziliga yozma bildirishnoma yuborish orqali "&'Общие данные'!B65&"" -> Mikromoliya tashkilotiga taqdim etilishi lozim. Garov shartnomasi belgilangan muddatda taqdim etilmagan hollarda, Mikromoliya tashkiloti Qarz oluvchining manziliga yozma bildirishnoma yuborish orqali mikroqarz | B34: berishni rad etish va / yoki ushbu shartnomani bir tomonlama bekor qilish huquqiga egadir. Bunda ushbu shartnoma Qarz oluvchi tomonidan talabnoma olingan vaqtda yoki talabnoma pochta xizmati orqali yuborilgandan keyin uchinchi kuni bekor qilingan hisoblanadi.
A35: 3.3. Asosiy qarzni, foizlar yoki ushbu shartnoma bo‘yicha belgilangan muddatdan kechiktirilganligi bo‘yicha penyalarni qaytarish muddati kechiktirilishi yuzaga kelganda va/yoki ushbu shartnoma bo‘yicha boshqa majburiyatlar buzilishi holatlarida Mikromoliya tashkiloti O‘zbekiston Respublikasining amaldagi qonunchiligiga muvofiq qarzni undirish uchun qaytarib olinmaydigan va muqarrar tartibda unidirishni garov ob'ektiga qaratish huquqiga ega bo‘ladi.
